{
 "cells": [
  {
   "cell_type": "code",
   "execution_count": 1,
   "metadata": {},
   "outputs": [],
   "source": [
    "from tensorflow.keras.datasets import mnist\n",
    "\n"
   ]
  },
  {
   "cell_type": "code",
   "execution_count": 2,
   "metadata": {},
   "outputs": [],
   "source": [
    "(train_images,train_labels),(test_images,test_labels) = mnist.load_data()"
   ]
  },
  {
   "cell_type": "code",
   "execution_count": 3,
   "metadata": {},
   "outputs": [
    {
     "data": {
      "text/plain": [
       "(60000, 28, 28)"
      ]
     },
     "execution_count": 3,
     "metadata": {},
     "output_type": "execute_result"
    }
   ],
   "source": [
    "train_images.shape"
   ]
  },
  {
   "cell_type": "code",
   "execution_count": 4,
   "metadata": {},
   "outputs": [
    {
     "data": {
      "text/plain": [
       "60000"
      ]
     },
     "execution_count": 4,
     "metadata": {},
     "output_type": "execute_result"
    }
   ],
   "source": [
    "len(train_labels)"
   ]
  },
  {
   "cell_type": "code",
   "execution_count": 5,
   "metadata": {},
   "outputs": [
    {
     "data": {
      "text/plain": [
       "array([5, 0, 4, ..., 5, 6, 8], dtype=uint8)"
      ]
     },
     "execution_count": 5,
     "metadata": {},
     "output_type": "execute_result"
    }
   ],
   "source": [
    "train_labels"
   ]
  },
  {
   "cell_type": "code",
   "execution_count": 6,
   "metadata": {},
   "outputs": [
    {
     "data": {
      "text/plain": [
       "(10000, 28, 28)"
      ]
     },
     "execution_count": 6,
     "metadata": {},
     "output_type": "execute_result"
    }
   ],
   "source": [
    "test_images.shape"
   ]
  },
  {
   "cell_type": "code",
   "execution_count": 7,
   "metadata": {},
   "outputs": [
    {
     "data": {
      "text/plain": [
       "10000"
      ]
     },
     "execution_count": 7,
     "metadata": {},
     "output_type": "execute_result"
    }
   ],
   "source": [
    "len(test_labels)"
   ]
  },
  {
   "cell_type": "code",
   "execution_count": 8,
   "metadata": {},
   "outputs": [
    {
     "data": {
      "text/plain": [
       "array([7, 2, 1, ..., 4, 5, 6], dtype=uint8)"
      ]
     },
     "execution_count": 8,
     "metadata": {},
     "output_type": "execute_result"
    }
   ],
   "source": [
    "test_labels"
   ]
  },
  {
   "cell_type": "code",
   "execution_count": 17,
   "metadata": {},
   "outputs": [],
   "source": [
    "from tensorflow import keras\n",
    "from tensorflow.keras import layers\n"
   ]
  },
  {
   "cell_type": "code",
   "execution_count": 18,
   "metadata": {},
   "outputs": [],
   "source": [
    "model = keras.Sequential([layers.Dense(512,activation = \"relu\"),\n",
    "                         layers.Dense(10,activation = \"softmax\")])"
   ]
  },
  {
   "cell_type": "code",
   "execution_count": 32,
   "metadata": {},
   "outputs": [],
   "source": [
    "model.compile(optimizer=\"rmsprop\", loss=\"sparse_categorical_crossentropy\", metrics=[\"accuracy\"])\n"
   ]
  },
  {
   "cell_type": "code",
   "execution_count": 20,
   "metadata": {},
   "outputs": [],
   "source": [
    "train_images = train_images.reshape((60000,28*28))"
   ]
  },
  {
   "cell_type": "code",
   "execution_count": 22,
   "metadata": {},
   "outputs": [],
   "source": [
    "train_images = train_images.astype(\"float32\")/255"
   ]
  },
  {
   "cell_type": "code",
   "execution_count": 35,
   "metadata": {},
   "outputs": [],
   "source": [
    "test_images = test_images.reshape((10000,28,28))"
   ]
  },
  {
   "cell_type": "code",
   "execution_count": 24,
   "metadata": {},
   "outputs": [],
   "source": [
    "test_images = test_images.astype(\"float32\")/255"
   ]
  },
  {
   "cell_type": "code",
   "execution_count": 37,
   "metadata": {},
   "outputs": [
    {
     "name": "stdout",
     "output_type": "stream",
     "text": [
      "Epoch 1/5\n"
     ]
    },
    {
     "ename": "InvalidArgumentError",
     "evalue": "Graph execution error:\n\nDetected at node StatefulPartitionedCall/sequential_1/dense_1/Relu defined at (most recent call last):\n<stack traces unavailable>\nIn[1] is not a matrix\n\t [[{{node StatefulPartitionedCall/sequential_1/dense_1/Relu}}]] [Op:__inference_one_step_on_iterator_1063]",
     "output_type": "error",
     "traceback": [
      "\u001b[1;31m---------------------------------------------------------------------------\u001b[0m",
      "\u001b[1;31mInvalidArgumentError\u001b[0m                      Traceback (most recent call last)",
      "Cell \u001b[1;32mIn[37], line 1\u001b[0m\n\u001b[1;32m----> 1\u001b[0m \u001b[43mmodel\u001b[49m\u001b[38;5;241;43m.\u001b[39;49m\u001b[43mfit\u001b[49m\u001b[43m(\u001b[49m\u001b[43mtrain_images\u001b[49m\u001b[43m,\u001b[49m\u001b[43m \u001b[49m\u001b[43mtrain_labels\u001b[49m\u001b[43m,\u001b[49m\u001b[43m \u001b[49m\u001b[43mepochs\u001b[49m\u001b[38;5;241;43m=\u001b[39;49m\u001b[38;5;241;43m5\u001b[39;49m\u001b[43m,\u001b[49m\u001b[43m \u001b[49m\u001b[43mbatch_size\u001b[49m\u001b[38;5;241;43m=\u001b[39;49m\u001b[38;5;241;43m128\u001b[39;49m\u001b[43m)\u001b[49m\n",
      "File \u001b[1;32mc:\\Users\\hansr\\AppData\\Local\\Programs\\Python\\Python312\\Lib\\site-packages\\keras\\src\\utils\\traceback_utils.py:122\u001b[0m, in \u001b[0;36mfilter_traceback.<locals>.error_handler\u001b[1;34m(*args, **kwargs)\u001b[0m\n\u001b[0;32m    119\u001b[0m     filtered_tb \u001b[38;5;241m=\u001b[39m _process_traceback_frames(e\u001b[38;5;241m.\u001b[39m__traceback__)\n\u001b[0;32m    120\u001b[0m     \u001b[38;5;66;03m# To get the full stack trace, call:\u001b[39;00m\n\u001b[0;32m    121\u001b[0m     \u001b[38;5;66;03m# `keras.config.disable_traceback_filtering()`\u001b[39;00m\n\u001b[1;32m--> 122\u001b[0m     \u001b[38;5;28;01mraise\u001b[39;00m e\u001b[38;5;241m.\u001b[39mwith_traceback(filtered_tb) \u001b[38;5;28;01mfrom\u001b[39;00m \u001b[38;5;28;01mNone\u001b[39;00m\n\u001b[0;32m    123\u001b[0m \u001b[38;5;28;01mfinally\u001b[39;00m:\n\u001b[0;32m    124\u001b[0m     \u001b[38;5;28;01mdel\u001b[39;00m filtered_tb\n",
      "File \u001b[1;32mc:\\Users\\hansr\\AppData\\Local\\Programs\\Python\\Python312\\Lib\\site-packages\\tensorflow\\python\\eager\\execute.py:53\u001b[0m, in \u001b[0;36mquick_execute\u001b[1;34m(op_name, num_outputs, inputs, attrs, ctx, name)\u001b[0m\n\u001b[0;32m     51\u001b[0m \u001b[38;5;28;01mtry\u001b[39;00m:\n\u001b[0;32m     52\u001b[0m   ctx\u001b[38;5;241m.\u001b[39mensure_initialized()\n\u001b[1;32m---> 53\u001b[0m   tensors \u001b[38;5;241m=\u001b[39m pywrap_tfe\u001b[38;5;241m.\u001b[39mTFE_Py_Execute(ctx\u001b[38;5;241m.\u001b[39m_handle, device_name, op_name,\n\u001b[0;32m     54\u001b[0m                                       inputs, attrs, num_outputs)\n\u001b[0;32m     55\u001b[0m \u001b[38;5;28;01mexcept\u001b[39;00m core\u001b[38;5;241m.\u001b[39m_NotOkStatusException \u001b[38;5;28;01mas\u001b[39;00m e:\n\u001b[0;32m     56\u001b[0m   \u001b[38;5;28;01mif\u001b[39;00m name \u001b[38;5;129;01mis\u001b[39;00m \u001b[38;5;129;01mnot\u001b[39;00m \u001b[38;5;28;01mNone\u001b[39;00m:\n",
      "\u001b[1;31mInvalidArgumentError\u001b[0m: Graph execution error:\n\nDetected at node StatefulPartitionedCall/sequential_1/dense_1/Relu defined at (most recent call last):\n<stack traces unavailable>\nIn[1] is not a matrix\n\t [[{{node StatefulPartitionedCall/sequential_1/dense_1/Relu}}]] [Op:__inference_one_step_on_iterator_1063]"
     ]
    }
   ],
   "source": [
    "model.fit(train_images, train_labels, epochs=5, batch_size=128)\n"
   ]
  },
  {
   "cell_type": "code",
   "execution_count": 28,
   "metadata": {},
   "outputs": [],
   "source": [
    "test_digits = test_images[0:10]"
   ]
  },
  {
   "cell_type": "code",
   "execution_count": 29,
   "metadata": {},
   "outputs": [
    {
     "ename": "InvalidArgumentError",
     "evalue": "Graph execution error:\n\nDetected at node sequential_1/dense_1/Relu defined at (most recent call last):\n  File \"<frozen runpy>\", line 198, in _run_module_as_main\n\n  File \"<frozen runpy>\", line 88, in _run_code\n\n  File \"c:\\Users\\hansr\\AppData\\Local\\Programs\\Python\\Python312\\Lib\\site-packages\\ipykernel_launcher.py\", line 18, in <module>\n\n  File \"c:\\Users\\hansr\\AppData\\Local\\Programs\\Python\\Python312\\Lib\\site-packages\\traitlets\\config\\application.py\", line 1075, in launch_instance\n\n  File \"c:\\Users\\hansr\\AppData\\Local\\Programs\\Python\\Python312\\Lib\\site-packages\\ipykernel\\kernelapp.py\", line 739, in start\n\n  File \"c:\\Users\\hansr\\AppData\\Local\\Programs\\Python\\Python312\\Lib\\site-packages\\tornado\\platform\\asyncio.py\", line 205, in start\n\n  File \"c:\\Users\\hansr\\AppData\\Local\\Programs\\Python\\Python312\\Lib\\asyncio\\base_events.py\", line 641, in run_forever\n\n  File \"c:\\Users\\hansr\\AppData\\Local\\Programs\\Python\\Python312\\Lib\\asyncio\\base_events.py\", line 1987, in _run_once\n\n  File \"c:\\Users\\hansr\\AppData\\Local\\Programs\\Python\\Python312\\Lib\\asyncio\\events.py\", line 88, in _run\n\n  File \"c:\\Users\\hansr\\AppData\\Local\\Programs\\Python\\Python312\\Lib\\site-packages\\ipykernel\\kernelbase.py\", line 545, in dispatch_queue\n\n  File \"c:\\Users\\hansr\\AppData\\Local\\Programs\\Python\\Python312\\Lib\\site-packages\\ipykernel\\kernelbase.py\", line 534, in process_one\n\n  File \"c:\\Users\\hansr\\AppData\\Local\\Programs\\Python\\Python312\\Lib\\site-packages\\ipykernel\\kernelbase.py\", line 437, in dispatch_shell\n\n  File \"c:\\Users\\hansr\\AppData\\Local\\Programs\\Python\\Python312\\Lib\\site-packages\\ipykernel\\ipkernel.py\", line 362, in execute_request\n\n  File \"c:\\Users\\hansr\\AppData\\Local\\Programs\\Python\\Python312\\Lib\\site-packages\\ipykernel\\kernelbase.py\", line 778, in execute_request\n\n  File \"c:\\Users\\hansr\\AppData\\Local\\Programs\\Python\\Python312\\Lib\\site-packages\\ipykernel\\ipkernel.py\", line 449, in do_execute\n\n  File \"c:\\Users\\hansr\\AppData\\Local\\Programs\\Python\\Python312\\Lib\\site-packages\\ipykernel\\zmqshell.py\", line 549, in run_cell\n\n  File \"c:\\Users\\hansr\\AppData\\Local\\Programs\\Python\\Python312\\Lib\\site-packages\\IPython\\core\\interactiveshell.py\", line 3075, in run_cell\n\n  File \"c:\\Users\\hansr\\AppData\\Local\\Programs\\Python\\Python312\\Lib\\site-packages\\IPython\\core\\interactiveshell.py\", line 3130, in _run_cell\n\n  File \"c:\\Users\\hansr\\AppData\\Local\\Programs\\Python\\Python312\\Lib\\site-packages\\IPython\\core\\async_helpers.py\", line 129, in _pseudo_sync_runner\n\n  File \"c:\\Users\\hansr\\AppData\\Local\\Programs\\Python\\Python312\\Lib\\site-packages\\IPython\\core\\interactiveshell.py\", line 3334, in run_cell_async\n\n  File \"c:\\Users\\hansr\\AppData\\Local\\Programs\\Python\\Python312\\Lib\\site-packages\\IPython\\core\\interactiveshell.py\", line 3517, in run_ast_nodes\n\n  File \"c:\\Users\\hansr\\AppData\\Local\\Programs\\Python\\Python312\\Lib\\site-packages\\IPython\\core\\interactiveshell.py\", line 3577, in run_code\n\n  File \"C:\\Users\\hansr\\AppData\\Local\\Temp\\ipykernel_16068\\1749547860.py\", line 1, in <module>\n\n  File \"c:\\Users\\hansr\\AppData\\Local\\Programs\\Python\\Python312\\Lib\\site-packages\\keras\\src\\utils\\traceback_utils.py\", line 117, in error_handler\n\n  File \"c:\\Users\\hansr\\AppData\\Local\\Programs\\Python\\Python312\\Lib\\site-packages\\keras\\src\\backend\\tensorflow\\trainer.py\", line 508, in predict\n\n  File \"c:\\Users\\hansr\\AppData\\Local\\Programs\\Python\\Python312\\Lib\\site-packages\\keras\\src\\backend\\tensorflow\\trainer.py\", line 208, in one_step_on_data_distributed\n\n  File \"c:\\Users\\hansr\\AppData\\Local\\Programs\\Python\\Python312\\Lib\\site-packages\\keras\\src\\backend\\tensorflow\\trainer.py\", line 198, in one_step_on_data\n\n  File \"c:\\Users\\hansr\\AppData\\Local\\Programs\\Python\\Python312\\Lib\\site-packages\\keras\\src\\backend\\tensorflow\\trainer.py\", line 96, in predict_step\n\n  File \"c:\\Users\\hansr\\AppData\\Local\\Programs\\Python\\Python312\\Lib\\site-packages\\keras\\src\\utils\\traceback_utils.py\", line 117, in error_handler\n\n  File \"c:\\Users\\hansr\\AppData\\Local\\Programs\\Python\\Python312\\Lib\\site-packages\\keras\\src\\layers\\layer.py\", line 882, in __call__\n\n  File \"c:\\Users\\hansr\\AppData\\Local\\Programs\\Python\\Python312\\Lib\\site-packages\\keras\\src\\utils\\traceback_utils.py\", line 117, in error_handler\n\n  File \"c:\\Users\\hansr\\AppData\\Local\\Programs\\Python\\Python312\\Lib\\site-packages\\keras\\src\\ops\\operation.py\", line 46, in __call__\n\n  File \"c:\\Users\\hansr\\AppData\\Local\\Programs\\Python\\Python312\\Lib\\site-packages\\keras\\src\\utils\\traceback_utils.py\", line 156, in error_handler\n\n  File \"c:\\Users\\hansr\\AppData\\Local\\Programs\\Python\\Python312\\Lib\\site-packages\\keras\\src\\models\\sequential.py\", line 209, in call\n\n  File \"c:\\Users\\hansr\\AppData\\Local\\Programs\\Python\\Python312\\Lib\\site-packages\\keras\\src\\models\\functional.py\", line 175, in call\n\n  File \"c:\\Users\\hansr\\AppData\\Local\\Programs\\Python\\Python312\\Lib\\site-packages\\keras\\src\\ops\\function.py\", line 171, in _run_through_graph\n\n  File \"c:\\Users\\hansr\\AppData\\Local\\Programs\\Python\\Python312\\Lib\\site-packages\\keras\\src\\models\\functional.py\", line 556, in call\n\n  File \"c:\\Users\\hansr\\AppData\\Local\\Programs\\Python\\Python312\\Lib\\site-packages\\keras\\src\\utils\\traceback_utils.py\", line 117, in error_handler\n\n  File \"c:\\Users\\hansr\\AppData\\Local\\Programs\\Python\\Python312\\Lib\\site-packages\\keras\\src\\layers\\layer.py\", line 882, in __call__\n\n  File \"c:\\Users\\hansr\\AppData\\Local\\Programs\\Python\\Python312\\Lib\\site-packages\\keras\\src\\utils\\traceback_utils.py\", line 117, in error_handler\n\n  File \"c:\\Users\\hansr\\AppData\\Local\\Programs\\Python\\Python312\\Lib\\site-packages\\keras\\src\\ops\\operation.py\", line 46, in __call__\n\n  File \"c:\\Users\\hansr\\AppData\\Local\\Programs\\Python\\Python312\\Lib\\site-packages\\keras\\src\\utils\\traceback_utils.py\", line 156, in error_handler\n\n  File \"c:\\Users\\hansr\\AppData\\Local\\Programs\\Python\\Python312\\Lib\\site-packages\\keras\\src\\layers\\core\\dense.py\", line 148, in call\n\n  File \"c:\\Users\\hansr\\AppData\\Local\\Programs\\Python\\Python312\\Lib\\site-packages\\keras\\src\\activations\\activations.py\", line 47, in relu\n\n  File \"c:\\Users\\hansr\\AppData\\Local\\Programs\\Python\\Python312\\Lib\\site-packages\\keras\\src\\activations\\activations.py\", line 99, in static_call\n\n  File \"c:\\Users\\hansr\\AppData\\Local\\Programs\\Python\\Python312\\Lib\\site-packages\\keras\\src\\backend\\tensorflow\\nn.py\", line 15, in relu\n\nIn[1] is not a matrix\n\t [[{{node sequential_1/dense_1/Relu}}]] [Op:__inference_one_step_on_data_distributed_329]",
     "output_type": "error",
     "traceback": [
      "\u001b[1;31m---------------------------------------------------------------------------\u001b[0m",
      "\u001b[1;31mInvalidArgumentError\u001b[0m                      Traceback (most recent call last)",
      "Cell \u001b[1;32mIn[29], line 1\u001b[0m\n\u001b[1;32m----> 1\u001b[0m predictions \u001b[38;5;241m=\u001b[39m \u001b[43mmodel\u001b[49m\u001b[43m \u001b[49m\u001b[38;5;241;43m.\u001b[39;49m\u001b[43mpredict\u001b[49m\u001b[43m(\u001b[49m\u001b[43mtest_digits\u001b[49m\u001b[43m)\u001b[49m\n",
      "File \u001b[1;32mc:\\Users\\hansr\\AppData\\Local\\Programs\\Python\\Python312\\Lib\\site-packages\\keras\\src\\utils\\traceback_utils.py:122\u001b[0m, in \u001b[0;36mfilter_traceback.<locals>.error_handler\u001b[1;34m(*args, **kwargs)\u001b[0m\n\u001b[0;32m    119\u001b[0m     filtered_tb \u001b[38;5;241m=\u001b[39m _process_traceback_frames(e\u001b[38;5;241m.\u001b[39m__traceback__)\n\u001b[0;32m    120\u001b[0m     \u001b[38;5;66;03m# To get the full stack trace, call:\u001b[39;00m\n\u001b[0;32m    121\u001b[0m     \u001b[38;5;66;03m# `keras.config.disable_traceback_filtering()`\u001b[39;00m\n\u001b[1;32m--> 122\u001b[0m     \u001b[38;5;28;01mraise\u001b[39;00m e\u001b[38;5;241m.\u001b[39mwith_traceback(filtered_tb) \u001b[38;5;28;01mfrom\u001b[39;00m \u001b[38;5;28;01mNone\u001b[39;00m\n\u001b[0;32m    123\u001b[0m \u001b[38;5;28;01mfinally\u001b[39;00m:\n\u001b[0;32m    124\u001b[0m     \u001b[38;5;28;01mdel\u001b[39;00m filtered_tb\n",
      "File \u001b[1;32mc:\\Users\\hansr\\AppData\\Local\\Programs\\Python\\Python312\\Lib\\site-packages\\tensorflow\\python\\eager\\execute.py:53\u001b[0m, in \u001b[0;36mquick_execute\u001b[1;34m(op_name, num_outputs, inputs, attrs, ctx, name)\u001b[0m\n\u001b[0;32m     51\u001b[0m \u001b[38;5;28;01mtry\u001b[39;00m:\n\u001b[0;32m     52\u001b[0m   ctx\u001b[38;5;241m.\u001b[39mensure_initialized()\n\u001b[1;32m---> 53\u001b[0m   tensors \u001b[38;5;241m=\u001b[39m pywrap_tfe\u001b[38;5;241m.\u001b[39mTFE_Py_Execute(ctx\u001b[38;5;241m.\u001b[39m_handle, device_name, op_name,\n\u001b[0;32m     54\u001b[0m                                       inputs, attrs, num_outputs)\n\u001b[0;32m     55\u001b[0m \u001b[38;5;28;01mexcept\u001b[39;00m core\u001b[38;5;241m.\u001b[39m_NotOkStatusException \u001b[38;5;28;01mas\u001b[39;00m e:\n\u001b[0;32m     56\u001b[0m   \u001b[38;5;28;01mif\u001b[39;00m name \u001b[38;5;129;01mis\u001b[39;00m \u001b[38;5;129;01mnot\u001b[39;00m \u001b[38;5;28;01mNone\u001b[39;00m:\n",
      "\u001b[1;31mInvalidArgumentError\u001b[0m: Graph execution error:\n\nDetected at node sequential_1/dense_1/Relu defined at (most recent call last):\n  File \"<frozen runpy>\", line 198, in _run_module_as_main\n\n  File \"<frozen runpy>\", line 88, in _run_code\n\n  File \"c:\\Users\\hansr\\AppData\\Local\\Programs\\Python\\Python312\\Lib\\site-packages\\ipykernel_launcher.py\", line 18, in <module>\n\n  File \"c:\\Users\\hansr\\AppData\\Local\\Programs\\Python\\Python312\\Lib\\site-packages\\traitlets\\config\\application.py\", line 1075, in launch_instance\n\n  File \"c:\\Users\\hansr\\AppData\\Local\\Programs\\Python\\Python312\\Lib\\site-packages\\ipykernel\\kernelapp.py\", line 739, in start\n\n  File \"c:\\Users\\hansr\\AppData\\Local\\Programs\\Python\\Python312\\Lib\\site-packages\\tornado\\platform\\asyncio.py\", line 205, in start\n\n  File \"c:\\Users\\hansr\\AppData\\Local\\Programs\\Python\\Python312\\Lib\\asyncio\\base_events.py\", line 641, in run_forever\n\n  File \"c:\\Users\\hansr\\AppData\\Local\\Programs\\Python\\Python312\\Lib\\asyncio\\base_events.py\", line 1987, in _run_once\n\n  File \"c:\\Users\\hansr\\AppData\\Local\\Programs\\Python\\Python312\\Lib\\asyncio\\events.py\", line 88, in _run\n\n  File \"c:\\Users\\hansr\\AppData\\Local\\Programs\\Python\\Python312\\Lib\\site-packages\\ipykernel\\kernelbase.py\", line 545, in dispatch_queue\n\n  File \"c:\\Users\\hansr\\AppData\\Local\\Programs\\Python\\Python312\\Lib\\site-packages\\ipykernel\\kernelbase.py\", line 534, in process_one\n\n  File \"c:\\Users\\hansr\\AppData\\Local\\Programs\\Python\\Python312\\Lib\\site-packages\\ipykernel\\kernelbase.py\", line 437, in dispatch_shell\n\n  File \"c:\\Users\\hansr\\AppData\\Local\\Programs\\Python\\Python312\\Lib\\site-packages\\ipykernel\\ipkernel.py\", line 362, in execute_request\n\n  File \"c:\\Users\\hansr\\AppData\\Local\\Programs\\Python\\Python312\\Lib\\site-packages\\ipykernel\\kernelbase.py\", line 778, in execute_request\n\n  File \"c:\\Users\\hansr\\AppData\\Local\\Programs\\Python\\Python312\\Lib\\site-packages\\ipykernel\\ipkernel.py\", line 449, in do_execute\n\n  File \"c:\\Users\\hansr\\AppData\\Local\\Programs\\Python\\Python312\\Lib\\site-packages\\ipykernel\\zmqshell.py\", line 549, in run_cell\n\n  File \"c:\\Users\\hansr\\AppData\\Local\\Programs\\Python\\Python312\\Lib\\site-packages\\IPython\\core\\interactiveshell.py\", line 3075, in run_cell\n\n  File \"c:\\Users\\hansr\\AppData\\Local\\Programs\\Python\\Python312\\Lib\\site-packages\\IPython\\core\\interactiveshell.py\", line 3130, in _run_cell\n\n  File \"c:\\Users\\hansr\\AppData\\Local\\Programs\\Python\\Python312\\Lib\\site-packages\\IPython\\core\\async_helpers.py\", line 129, in _pseudo_sync_runner\n\n  File \"c:\\Users\\hansr\\AppData\\Local\\Programs\\Python\\Python312\\Lib\\site-packages\\IPython\\core\\interactiveshell.py\", line 3334, in run_cell_async\n\n  File \"c:\\Users\\hansr\\AppData\\Local\\Programs\\Python\\Python312\\Lib\\site-packages\\IPython\\core\\interactiveshell.py\", line 3517, in run_ast_nodes\n\n  File \"c:\\Users\\hansr\\AppData\\Local\\Programs\\Python\\Python312\\Lib\\site-packages\\IPython\\core\\interactiveshell.py\", line 3577, in run_code\n\n  File \"C:\\Users\\hansr\\AppData\\Local\\Temp\\ipykernel_16068\\1749547860.py\", line 1, in <module>\n\n  File \"c:\\Users\\hansr\\AppData\\Local\\Programs\\Python\\Python312\\Lib\\site-packages\\keras\\src\\utils\\traceback_utils.py\", line 117, in error_handler\n\n  File \"c:\\Users\\hansr\\AppData\\Local\\Programs\\Python\\Python312\\Lib\\site-packages\\keras\\src\\backend\\tensorflow\\trainer.py\", line 508, in predict\n\n  File \"c:\\Users\\hansr\\AppData\\Local\\Programs\\Python\\Python312\\Lib\\site-packages\\keras\\src\\backend\\tensorflow\\trainer.py\", line 208, in one_step_on_data_distributed\n\n  File \"c:\\Users\\hansr\\AppData\\Local\\Programs\\Python\\Python312\\Lib\\site-packages\\keras\\src\\backend\\tensorflow\\trainer.py\", line 198, in one_step_on_data\n\n  File \"c:\\Users\\hansr\\AppData\\Local\\Programs\\Python\\Python312\\Lib\\site-packages\\keras\\src\\backend\\tensorflow\\trainer.py\", line 96, in predict_step\n\n  File \"c:\\Users\\hansr\\AppData\\Local\\Programs\\Python\\Python312\\Lib\\site-packages\\keras\\src\\utils\\traceback_utils.py\", line 117, in error_handler\n\n  File \"c:\\Users\\hansr\\AppData\\Local\\Programs\\Python\\Python312\\Lib\\site-packages\\keras\\src\\layers\\layer.py\", line 882, in __call__\n\n  File \"c:\\Users\\hansr\\AppData\\Local\\Programs\\Python\\Python312\\Lib\\site-packages\\keras\\src\\utils\\traceback_utils.py\", line 117, in error_handler\n\n  File \"c:\\Users\\hansr\\AppData\\Local\\Programs\\Python\\Python312\\Lib\\site-packages\\keras\\src\\ops\\operation.py\", line 46, in __call__\n\n  File \"c:\\Users\\hansr\\AppData\\Local\\Programs\\Python\\Python312\\Lib\\site-packages\\keras\\src\\utils\\traceback_utils.py\", line 156, in error_handler\n\n  File \"c:\\Users\\hansr\\AppData\\Local\\Programs\\Python\\Python312\\Lib\\site-packages\\keras\\src\\models\\sequential.py\", line 209, in call\n\n  File \"c:\\Users\\hansr\\AppData\\Local\\Programs\\Python\\Python312\\Lib\\site-packages\\keras\\src\\models\\functional.py\", line 175, in call\n\n  File \"c:\\Users\\hansr\\AppData\\Local\\Programs\\Python\\Python312\\Lib\\site-packages\\keras\\src\\ops\\function.py\", line 171, in _run_through_graph\n\n  File \"c:\\Users\\hansr\\AppData\\Local\\Programs\\Python\\Python312\\Lib\\site-packages\\keras\\src\\models\\functional.py\", line 556, in call\n\n  File \"c:\\Users\\hansr\\AppData\\Local\\Programs\\Python\\Python312\\Lib\\site-packages\\keras\\src\\utils\\traceback_utils.py\", line 117, in error_handler\n\n  File \"c:\\Users\\hansr\\AppData\\Local\\Programs\\Python\\Python312\\Lib\\site-packages\\keras\\src\\layers\\layer.py\", line 882, in __call__\n\n  File \"c:\\Users\\hansr\\AppData\\Local\\Programs\\Python\\Python312\\Lib\\site-packages\\keras\\src\\utils\\traceback_utils.py\", line 117, in error_handler\n\n  File \"c:\\Users\\hansr\\AppData\\Local\\Programs\\Python\\Python312\\Lib\\site-packages\\keras\\src\\ops\\operation.py\", line 46, in __call__\n\n  File \"c:\\Users\\hansr\\AppData\\Local\\Programs\\Python\\Python312\\Lib\\site-packages\\keras\\src\\utils\\traceback_utils.py\", line 156, in error_handler\n\n  File \"c:\\Users\\hansr\\AppData\\Local\\Programs\\Python\\Python312\\Lib\\site-packages\\keras\\src\\layers\\core\\dense.py\", line 148, in call\n\n  File \"c:\\Users\\hansr\\AppData\\Local\\Programs\\Python\\Python312\\Lib\\site-packages\\keras\\src\\activations\\activations.py\", line 47, in relu\n\n  File \"c:\\Users\\hansr\\AppData\\Local\\Programs\\Python\\Python312\\Lib\\site-packages\\keras\\src\\activations\\activations.py\", line 99, in static_call\n\n  File \"c:\\Users\\hansr\\AppData\\Local\\Programs\\Python\\Python312\\Lib\\site-packages\\keras\\src\\backend\\tensorflow\\nn.py\", line 15, in relu\n\nIn[1] is not a matrix\n\t [[{{node sequential_1/dense_1/Relu}}]] [Op:__inference_one_step_on_data_distributed_329]"
     ]
    }
   ],
   "source": [
    "predictions = model .predict(test_digits)"
   ]
  },
  {
   "cell_type": "code",
   "execution_count": 30,
   "metadata": {},
   "outputs": [
    {
     "ename": "NameError",
     "evalue": "name 'predictions' is not defined",
     "output_type": "error",
     "traceback": [
      "\u001b[1;31m---------------------------------------------------------------------------\u001b[0m",
      "\u001b[1;31mNameError\u001b[0m                                 Traceback (most recent call last)",
      "Cell \u001b[1;32mIn[30], line 1\u001b[0m\n\u001b[1;32m----> 1\u001b[0m \u001b[43mpredictions\u001b[49m[\u001b[38;5;241m0\u001b[39m]\n",
      "\u001b[1;31mNameError\u001b[0m: name 'predictions' is not defined"
     ]
    }
   ],
   "source": [
    "predictions[0]"
   ]
  },
  {
   "cell_type": "code",
   "execution_count": null,
   "metadata": {},
   "outputs": [],
   "source": [
    "test_loss,test_acc"
   ]
  }
 ],
 "metadata": {
  "kernelspec": {
   "display_name": "Python 3",
   "language": "python",
   "name": "python3"
  },
  "language_info": {
   "codemirror_mode": {
    "name": "ipython",
    "version": 3
   },
   "file_extension": ".py",
   "mimetype": "text/x-python",
   "name": "python",
   "nbconvert_exporter": "python",
   "pygments_lexer": "ipython3",
   "version": "3.12.4"
  }
 },
 "nbformat": 4,
 "nbformat_minor": 2
}
